<?xml version="1.0" ?>
<!-- =================================================================================== -->
<!-- |    This document was autogenerated by xacro from spotarm_assembly_description/urdf/spotarm_assembly.xacro | -->
<!-- |    EDITING THIS FILE BY HAND IS NOT RECOMMENDED                                 | -->
<!-- =================================================================================== -->
<robot name="spotarm_assembly">
  <material name="silver">
    <color rgba="0.700 0.700 0.700 1.000"/>
  </material>
  <transmission name="Revolute1_tran">
    <type>transmission_interface/SimpleTransmission</type>
    <joint name="Revolute1">
      <hardwareInterface>hardware_interface/EffortJointInterface</hardwareInterface>
    </joint>
    <actuator name="Revolute1_actr">
      <hardwareInterface>hardware_interface/EffortJointInterface</hardwareInterface>
      <mechanicalReduction>1</mechanicalReduction>
    </actuator>
  </transmission>
  <transmission name="Revolute2_tran">
    <type>transmission_interface/SimpleTransmission</type>
    <joint name="Revolute2">
      <hardwareInterface>hardware_interface/EffortJointInterface</hardwareInterface>
    </joint>
    <actuator name="Revolute2_actr">
      <hardwareInterface>hardware_interface/EffortJointInterface</hardwareInterface>
      <mechanicalReduction>1</mechanicalReduction>
    </actuator>
  </transmission>
  <transmission name="Revolute3_tran">
    <type>transmission_interface/SimpleTransmission</type>
    <joint name="Revolute3">
      <hardwareInterface>hardware_interface/EffortJointInterface</hardwareInterface>
    </joint>
    <actuator name="Revolute3_actr">
      <hardwareInterface>hardware_interface/EffortJointInterface</hardwareInterface>
      <mechanicalReduction>1</mechanicalReduction>
    </actuator>
  </transmission>
  <transmission name="Revolute4_tran">
    <type>transmission_interface/SimpleTransmission</type>
    <joint name="Revolute4">
      <hardwareInterface>hardware_interface/EffortJointInterface</hardwareInterface>
    </joint>
    <actuator name="Revolute4_actr">
      <hardwareInterface>hardware_interface/EffortJointInterface</hardwareInterface>
      <mechanicalReduction>1</mechanicalReduction>
    </actuator>
  </transmission>
  <transmission name="Revolute5_tran">
    <type>transmission_interface/SimpleTransmission</type>
    <joint name="Revolute5">
      <hardwareInterface>hardware_interface/EffortJointInterface</hardwareInterface>
    </joint>
    <actuator name="Revolute5_actr">
      <hardwareInterface>hardware_interface/EffortJointInterface</hardwareInterface>
      <mechanicalReduction>1</mechanicalReduction>
    </actuator>
  </transmission>
  <gazebo>
    <plugin filename="libgazebo_ros_control.so" name="control"/>
  </gazebo>
  <gazebo reference="base_link">
    <material>Gazebo/Silver</material>
    <mu1>0.2</mu1>
    <mu2>0.2</mu2>
    <self_collide>true</self_collide>
    <gravity>true</gravity>
  </gazebo>
  <gazebo reference="link_2">
    <material>Gazebo/Silver</material>
    <mu1>0.2</mu1>
    <mu2>0.2</mu2>
    <self_collide>true</self_collide>
  </gazebo>
  <gazebo reference="link_3">
    <material>Gazebo/Silver</material>
    <mu1>0.2</mu1>
    <mu2>0.2</mu2>
    <self_collide>true</self_collide>
  </gazebo>
  <gazebo reference="link_4">
    <material>Gazebo/Silver</material>
    <mu1>0.2</mu1>
    <mu2>0.2</mu2>
    <self_collide>true</self_collide>
  </gazebo>
  <gazebo reference="link_5">
    <material>Gazebo/Silver</material>
    <mu1>0.2</mu1>
    <mu2>0.2</mu2>
    <self_collide>true</self_collide>
  </gazebo>
  <gazebo reference="stub_link">
    <material>Gazebo/Silver</material>
    <mu1>0.2</mu1>
    <mu2>0.2</mu2>
    <self_collide>true</self_collide>
  </gazebo>
  <link name="base_link">
    <inertial>
      <origin rpy="0 0 0" xyz="-0.0010206433535600843 0.05102477807067246 0.07813725800807331"/>
      <mass value="3.2658781369547176"/>
      <inertia ixx="0.017479" ixy="0.003033" ixz="0.002731" iyy="0.012386" iyz="-0.005858" izz="0.01115"/>
    </inertial>
    <visual>
      <origin rpy="0 0 0" xyz="0 0 0"/>
      <geometry>
        <mesh filename="file:///home/chungus/msd_robot_arm_2/install/spotarm_assembly_description/share/spotarm_assembly_description/meshes/base_link.stl" scale="0.001 0.001 0.001"/>
      </geometry>
      <material name="silver"/>
    </visual>
    <collision>
      <origin rpy="0 0 0" xyz="0 0 0"/>
      <geometry>
        <mesh filename="file:///home/chungus/msd_robot_arm_2/install/spotarm_assembly_description/share/spotarm_assembly_description/meshes/base_link.stl" scale="0.001 0.001 0.001"/>
      </geometry>
    </collision>
  </link>
  <link name="link_2">
    <inertial>
      <origin rpy="0 0 0" xyz="-0.012527874109626764 -0.0005474727478518779 0.05618235883344737"/>
      <mass value="7.133736370057803"/>
      <inertia ixx="0.013679" ixy="0.000278" ixz="0.002124" iyy="0.018159" iyz="-0.000219" izz="0.014137"/>
    </inertial>
    <visual>
      <origin rpy="0 0 0" xyz="-0.02835 0.011972 -0.033179"/>
      <geometry>
        <mesh filename="file:///home/chungus/msd_robot_arm_2/install/spotarm_assembly_description/share/spotarm_assembly_description/meshes/Joint_2_Component_v2_1.stl" scale="0.001 0.001 0.001"/>
      </geometry>
      <material name="silver"/>
    </visual>
    <collision>
      <origin rpy="0 0 0" xyz="-0.02835 0.011972 -0.033179"/>
      <geometry>
        <mesh filename="file:///home/chungus/msd_robot_arm_2/install/spotarm_assembly_description/share/spotarm_assembly_description/meshes/Joint_2_Component_v2_1.stl" scale="0.001 0.001 0.001"/>
      </geometry>
    </collision>
  </link>
  <link name="link_3">
    <inertial>
      <origin rpy="0 0 0" xyz="-0.0023570645830831988 -0.2070530002719938 0.00014934365865988675"/>
      <mass value="9.269532978574247"/>
      <inertia ixx="0.160341" ixy="-1.4e-05" ixz="-0.00018" iyy="0.013913" iyz="1.2e-05" izz="0.160804"/>
    </inertial>
    <visual>
      <origin rpy="0 0 0" xyz="-0.074358 0.011972 -0.109385"/>
      <geometry>
        <mesh filename="file:///home/chungus/msd_robot_arm_2/install/spotarm_assembly_description/share/spotarm_assembly_description/meshes/Joint_3_Component_v2_1.stl" scale="0.001 0.001 0.001"/>
      </geometry>
      <material name="silver"/>
    </visual>
    <collision>
      <origin rpy="0 0 0" xyz="-0.074358 0.011972 -0.109385"/>
      <geometry>
        <mesh filename="file:///home/chungus/msd_robot_arm_2/install/spotarm_assembly_description/share/spotarm_assembly_description/meshes/Joint_3_Component_v2_1.stl" scale="0.001 0.001 0.001"/>
      </geometry>
    </collision>
  </link>
  <link name="link_4">
    <inertial>
      <origin rpy="0 0 0" xyz="-0.014428046075399614 -0.08611675195042084 -0.0016741934805408476"/>
      <mass value="7.656189719749854"/>
      <inertia ixx="0.044687" ixy="0.000767" ixz="1.1e-05" iyy="0.011252" iyz="-0.000125" izz="0.043172"/>
    </inertial>
    <visual>
      <origin rpy="0 0 0" xyz="-0.001798 0.325662 -0.109385"/>
      <geometry>
        <mesh filename="file:///home/chungus/msd_robot_arm_2/install/spotarm_assembly_description/share/spotarm_assembly_description/meshes/Joint_4_Component_v2_1.stl" scale="0.001 0.001 0.001"/>
      </geometry>
      <material name="silver"/>
    </visual>
    <collision>
      <origin rpy="0 0 0" xyz="-0.001798 0.325662 -0.109385"/>
      <geometry>
        <mesh filename="file:///home/chungus/msd_robot_arm_2/install/spotarm_assembly_description/share/spotarm_assembly_description/meshes/Joint_4_Component_v2_1.stl" scale="0.001 0.001 0.001"/>
      </geometry>
    </collision>
  </link>
  <link name="link_5">
    <inertial>
      <origin rpy="0 0 0" xyz="-8.830559206677441e-05 -0.10284977811786078 -0.00047877688390274287"/>
      <mass value="6.8508373998013345"/>
      <inertia ixx="0.031632" ixy="0.000268" ixz="3.9e-05" iyy="0.012107" iyz="-7.5e-05" izz="0.032684"/>
    </inertial>
    <visual>
      <origin rpy="0 0 0" xyz="0.010663 0.537462 -0.109385"/>
      <geometry>
        <mesh filename="file:///home/chungus/msd_robot_arm_2/install/spotarm_assembly_description/share/spotarm_assembly_description/meshes/Joint_5_Component_v2_1.stl" scale="0.001 0.001 0.001"/>
      </geometry>
      <material name="silver"/>
    </visual>
    <collision>
      <origin rpy="0 0 0" xyz="0.010663 0.537462 -0.109385"/>
      <geometry>
        <mesh filename="file:///home/chungus/msd_robot_arm_2/install/spotarm_assembly_description/share/spotarm_assembly_description/meshes/Joint_5_Component_v2_1.stl" scale="0.001 0.001 0.001"/>
      </geometry>
    </collision>
  </link>
  <link name="stub_link">
    <inertial>
      <origin rpy="0 0 0" xyz="0.011 0 0"/>
      <mass value="0.2"/>
      <inertia ixx="1.3333333333333334e-05" ixy="0.0" ixz="0.0" iyy="4.8333333333333334e-05" iyz="0.0" izz="4.8333333333333334e-05"/>
    </inertial>
    <visual>
      <origin rpy="0 0 0" xyz="0.011 -0.14 0"/>
      <geometry>
        <box size="0.02 0.3 0.02"/>
      </geometry>
      <material name="silver"/>
    </visual>
    <collision>
      <origin rpy="0 0 0" xyz="0.011 0 0"/>
      <geometry>
        <box size="0.02 0.05 0.02"/>
      </geometry>
    </collision>
  </link>
  <joint name="Revolute1" type="continuous">
    <origin rpy="0 0 0" xyz="0.02835 -0.011972 0.033179"/>
    <parent link="base_link"/>
    <child link="link_2"/>
    <axis xyz="-0.0 0.0 1.0"/>
  </joint>
  <joint name="Revolute2" type="continuous">
    <origin rpy="0 0 0" xyz="0.046008 0.0 0.076206"/>
    <parent link="link_2"/>
    <child link="link_3"/>
    <axis xyz="1.0 -0.0 -0.0"/>
  </joint>
  <joint name="Revolute3" type="continuous">
    <origin rpy="0 0 0" xyz="-0.07256 -0.31369 0.0"/>
    <parent link="link_3"/>
    <child link="link_4"/>
    <axis xyz="-1.0 0.0 0.0"/>
  </joint>
  <joint name="Revolute4" type="continuous">
    <origin rpy="0 0 0" xyz="-0.012461 -0.2118 0.0"/>
    <parent link="link_4"/>
    <child link="link_5"/>
    <axis xyz="-0.0 -1.0 0.0"/>
  </joint>
  <joint name="Revolute5" type="continuous">
    <origin rpy="0 0 0" xyz="0.07 -0.144 0"/>
    <parent link="link_5"/>
    <child link="stub_link"/>
    <axis xyz="1.0 0.0 0.0"/>
  </joint>
</robot>
